2025-06-19 00:53:27,140 - ExtractorManager - INFO - Registered extractor: GenericBlogExtractor
2025-06-19 00:53:27,182 - ExtractorManager - INFO - Registered extractor: GitHubExtractor
2025-06-19 00:53:27,196 - ExtractorManager - INFO - Registered extractor: MarkdownExtractor
2025-06-19 00:53:27,359 - ExtractorManager - INFO - Registered extractor: PDFExtractor
2025-06-19 00:53:27,361 - ExtractorManager - INFO - Registered extractor: SubstackExtractor
2025-06-19 00:53:27,362 - root - INFO - Successfully registered 5 extractors
2025-06-19 00:53:27,364 - ExtractorManager - INFO - Registered extractor: GenericBlogExtractor
2025-06-19 00:53:27,387 - ExtractorManager - INFO - Registered extractor: GitHubExtractor
2025-06-19 00:53:27,388 - ExtractorManager - INFO - Registered extractor: MarkdownExtractor
2025-06-19 00:53:27,388 - ExtractorManager - INFO - Registered extractor: PDFExtractor
2025-06-19 00:53:27,389 - ExtractorManager - INFO - Registered extractor: SubstackExtractor
2025-06-19 00:53:27,390 - root - INFO - Successfully registered 5 extractors
2025-06-19 00:53:27,394 - ExtractorManager - INFO - Registered extractor: GenericBlogExtractor
2025-06-19 00:53:27,395 - ExtractorManager - INFO - Registered extractor: GitHubExtractor
2025-06-19 00:53:27,396 - ExtractorManager - INFO - Registered extractor: MarkdownExtractor
2025-06-19 00:53:27,397 - ExtractorManager - INFO - Registered extractor: PDFExtractor
2025-06-19 00:53:27,398 - ExtractorManager - INFO - Registered extractor: SubstackExtractor
2025-06-19 00:53:27,398 - root - INFO - Successfully registered 5 extractors
2025-06-19 00:53:27,399 - ExtractorManager - INFO - Using GenericBlogExtractor for https://blog.openai.com/
2025-06-19 00:53:27,400 - GenericBlogExtractor - INFO - Extracting content from generic blog: https://blog.openai.com/
2025-06-19 00:53:27,499 - GenericBlogExtractor - ERROR - Failed to fetch URL https://blog.openai.com/: HTTPSConnectionPool(host='blog.openai.com', port=443): Max retries exceeded with url: / (Caused by NameResolutionError("<urllib3.connection.HTTPSConnection object at 0x000002117F6DFD10>: Failed to resolve 'blog.openai.com' ([Errno 11001] getaddrinfo failed)"))
Traceback (most recent call last):
  File "C:\Users\mishr\AppData\Local\Packages\PythonSoftwareFoundation.Python.3.11_qbz5n2kfra8p0\LocalCache\local-packages\Python311\site-packages\urllib3\connection.py", line 198, in _new_conn
    sock = connection.create_connection(
           ^^^^^^^^^^^^^^^^^^^^^^^^^^^^^
  File "C:\Users\mishr\AppData\Local\Packages\PythonSoftwareFoundation.Python.3.11_qbz5n2kfra8p0\LocalCache\local-packages\Python311\site-packages\urllib3\util\connection.py", line 60, in create_connection
    for res in socket.getaddrinfo(host, port, family, socket.SOCK_STREAM):
               ^^^^^^^^^^^^^^^^^^^^^^^^^^^^^^^^^^^^^^^^^^^^^^^^^^^^^^^^^^
  File "C:\Program Files\WindowsApps\PythonSoftwareFoundation.Python.3.11_3.11.2544.0_x64__qbz5n2kfra8p0\Lib\socket.py", line 962, in getaddrinfo
    for res in _socket.getaddrinfo(host, port, family, type, proto, flags):
               ^^^^^^^^^^^^^^^^^^^^^^^^^^^^^^^^^^^^^^^^^^^^^^^^^^^^^^^^^^^
socket.gaierror: [Errno 11001] getaddrinfo failed

The above exception was the direct cause of the following exception:

Traceback (most recent call last):
  File "C:\Users\mishr\AppData\Local\Packages\PythonSoftwareFoundation.Python.3.11_qbz5n2kfra8p0\LocalCache\local-packages\Python311\site-packages\urllib3\connectionpool.py", line 787, in urlopen
    response = self._make_request(
               ^^^^^^^^^^^^^^^^^^^
  File "C:\Users\mishr\AppData\Local\Packages\PythonSoftwareFoundation.Python.3.11_qbz5n2kfra8p0\LocalCache\local-packages\Python311\site-packages\urllib3\connectionpool.py", line 488, in _make_request
    raise new_e
  File "C:\Users\mishr\AppData\Local\Packages\PythonSoftwareFoundation.Python.3.11_qbz5n2kfra8p0\LocalCache\local-packages\Python311\site-packages\urllib3\connectionpool.py", line 464, in _make_request
    self._validate_conn(conn)
  File "C:\Users\mishr\AppData\Local\Packages\PythonSoftwareFoundation.Python.3.11_qbz5n2kfra8p0\LocalCache\local-packages\Python311\site-packages\urllib3\connectionpool.py", line 1093, in _validate_conn
    conn.connect()
  File "C:\Users\mishr\AppData\Local\Packages\PythonSoftwareFoundation.Python.3.11_qbz5n2kfra8p0\LocalCache\local-packages\Python311\site-packages\urllib3\connection.py", line 704, in connect
    self.sock = sock = self._new_conn()
                       ^^^^^^^^^^^^^^^^
  File "C:\Users\mishr\AppData\Local\Packages\PythonSoftwareFoundation.Python.3.11_qbz5n2kfra8p0\LocalCache\local-packages\Python311\site-packages\urllib3\connection.py", line 205, in _new_conn
    raise NameResolutionError(self.host, self, e) from e
urllib3.exceptions.NameResolutionError: <urllib3.connection.HTTPSConnection object at 0x000002117F6DFD10>: Failed to resolve 'blog.openai.com' ([Errno 11001] getaddrinfo failed)

The above exception was the direct cause of the following exception:

Traceback (most recent call last):
  File "C:\Users\mishr\AppData\Local\Packages\PythonSoftwareFoundation.Python.3.11_qbz5n2kfra8p0\LocalCache\local-packages\Python311\site-packages\requests\adapters.py", line 667, in send
    resp = conn.urlopen(
           ^^^^^^^^^^^^^
  File "C:\Users\mishr\AppData\Local\Packages\PythonSoftwareFoundation.Python.3.11_qbz5n2kfra8p0\LocalCache\local-packages\Python311\site-packages\urllib3\connectionpool.py", line 841, in urlopen
    retries = retries.increment(
              ^^^^^^^^^^^^^^^^^^
  File "C:\Users\mishr\AppData\Local\Packages\PythonSoftwareFoundation.Python.3.11_qbz5n2kfra8p0\LocalCache\local-packages\Python311\site-packages\urllib3\util\retry.py", line 519, in increment
    raise MaxRetryError(_pool, url, reason) from reason  # type: ignore[arg-type]
    ^^^^^^^^^^^^^^^^^^^^^^^^^^^^^^^^^^^^^^^^^^^^^^^^^^^
urllib3.exceptions.MaxRetryError: HTTPSConnectionPool(host='blog.openai.com', port=443): Max retries exceeded with url: / (Caused by NameResolutionError("<urllib3.connection.HTTPSConnection object at 0x000002117F6DFD10>: Failed to resolve 'blog.openai.com' ([Errno 11001] getaddrinfo failed)"))

During handling of the above exception, another exception occurred:

Traceback (most recent call last):
  File "C:\Users\mishr\Desktop\OGtool\content_extraction\extractors\blog.py", line 105, in _fetch_url
    response = requests.get(url, headers=self.headers, timeout=30)
               ^^^^^^^^^^^^^^^^^^^^^^^^^^^^^^^^^^^^^^^^^^^^^^^^^^^
  File "C:\Users\mishr\AppData\Local\Packages\PythonSoftwareFoundation.Python.3.11_qbz5n2kfra8p0\LocalCache\local-packages\Python311\site-packages\requests\api.py", line 73, in get
    return request("get", url, params=params, **kwargs)
           ^^^^^^^^^^^^^^^^^^^^^^^^^^^^^^^^^^^^^^^^^^^^
  File "C:\Users\mishr\AppData\Local\Packages\PythonSoftwareFoundation.Python.3.11_qbz5n2kfra8p0\LocalCache\local-packages\Python311\site-packages\requests\api.py", line 59, in request
    return session.request(method=method, url=url, **kwargs)
           ^^^^^^^^^^^^^^^^^^^^^^^^^^^^^^^^^^^^^^^^^^^^^^^^^
  File "C:\Users\mishr\AppData\Local\Packages\PythonSoftwareFoundation.Python.3.11_qbz5n2kfra8p0\LocalCache\local-packages\Python311\site-packages\requests\sessions.py", line 589, in request
    resp = self.send(prep, **send_kwargs)
           ^^^^^^^^^^^^^^^^^^^^^^^^^^^^^^
  File "C:\Users\mishr\AppData\Local\Packages\PythonSoftwareFoundation.Python.3.11_qbz5n2kfra8p0\LocalCache\local-packages\Python311\site-packages\requests\sessions.py", line 703, in send
    r = adapter.send(request, **kwargs)
        ^^^^^^^^^^^^^^^^^^^^^^^^^^^^^^^
  File "C:\Users\mishr\AppData\Local\Packages\PythonSoftwareFoundation.Python.3.11_qbz5n2kfra8p0\LocalCache\local-packages\Python311\site-packages\requests\adapters.py", line 700, in send
    raise ConnectionError(e, request=request)
requests.exceptions.ConnectionError: HTTPSConnectionPool(host='blog.openai.com', port=443): Max retries exceeded with url: / (Caused by NameResolutionError("<urllib3.connection.HTTPSConnection object at 0x000002117F6DFD10>: Failed to resolve 'blog.openai.com' ([Errno 11001] getaddrinfo failed)"))
2025-06-19 00:53:27,508 - GenericBlogExtractor - ERROR - Failed to fetch URL: https://blog.openai.com/
2025-06-19 00:53:27,508 - ExtractorManager - INFO - Using GenericBlogExtractor for https://github.blog/
2025-06-19 00:53:27,509 - GenericBlogExtractor - INFO - Extracting content from generic blog: https://github.blog/
2025-06-19 00:53:27,963 - GenericBlogExtractor - INFO - Extracted 1 item(s) from https://github.blog/
2025-06-19 00:53:27,964 - ExtractorManager - INFO - Using GenericBlogExtractor for https://nonexistent-blog-xyz.com/
2025-06-19 00:53:27,965 - GenericBlogExtractor - INFO - Extracting content from generic blog: https://nonexistent-blog-xyz.com/
2025-06-19 00:53:28,018 - GenericBlogExtractor - ERROR - Failed to fetch URL https://nonexistent-blog-xyz.com/: HTTPSConnectionPool(host='nonexistent-blog-xyz.com', port=443): Max retries exceeded with url: / (Caused by NameResolutionError("<urllib3.connection.HTTPSConnection object at 0x00000211817E4550>: Failed to resolve 'nonexistent-blog-xyz.com' ([Errno 11001] getaddrinfo failed)"))
Traceback (most recent call last):
  File "C:\Users\mishr\AppData\Local\Packages\PythonSoftwareFoundation.Python.3.11_qbz5n2kfra8p0\LocalCache\local-packages\Python311\site-packages\urllib3\connection.py", line 198, in _new_conn
    sock = connection.create_connection(
           ^^^^^^^^^^^^^^^^^^^^^^^^^^^^^
  File "C:\Users\mishr\AppData\Local\Packages\PythonSoftwareFoundation.Python.3.11_qbz5n2kfra8p0\LocalCache\local-packages\Python311\site-packages\urllib3\util\connection.py", line 60, in create_connection
    for res in socket.getaddrinfo(host, port, family, socket.SOCK_STREAM):
               ^^^^^^^^^^^^^^^^^^^^^^^^^^^^^^^^^^^^^^^^^^^^^^^^^^^^^^^^^^
  File "C:\Program Files\WindowsApps\PythonSoftwareFoundation.Python.3.11_3.11.2544.0_x64__qbz5n2kfra8p0\Lib\socket.py", line 962, in getaddrinfo
    for res in _socket.getaddrinfo(host, port, family, type, proto, flags):
               ^^^^^^^^^^^^^^^^^^^^^^^^^^^^^^^^^^^^^^^^^^^^^^^^^^^^^^^^^^^
socket.gaierror: [Errno 11001] getaddrinfo failed

The above exception was the direct cause of the following exception:

Traceback (most recent call last):
  File "C:\Users\mishr\AppData\Local\Packages\PythonSoftwareFoundation.Python.3.11_qbz5n2kfra8p0\LocalCache\local-packages\Python311\site-packages\urllib3\connectionpool.py", line 787, in urlopen
    response = self._make_request(
               ^^^^^^^^^^^^^^^^^^^
  File "C:\Users\mishr\AppData\Local\Packages\PythonSoftwareFoundation.Python.3.11_qbz5n2kfra8p0\LocalCache\local-packages\Python311\site-packages\urllib3\connectionpool.py", line 488, in _make_request
    raise new_e
  File "C:\Users\mishr\AppData\Local\Packages\PythonSoftwareFoundation.Python.3.11_qbz5n2kfra8p0\LocalCache\local-packages\Python311\site-packages\urllib3\connectionpool.py", line 464, in _make_request
    self._validate_conn(conn)
  File "C:\Users\mishr\AppData\Local\Packages\PythonSoftwareFoundation.Python.3.11_qbz5n2kfra8p0\LocalCache\local-packages\Python311\site-packages\urllib3\connectionpool.py", line 1093, in _validate_conn
    conn.connect()
  File "C:\Users\mishr\AppData\Local\Packages\PythonSoftwareFoundation.Python.3.11_qbz5n2kfra8p0\LocalCache\local-packages\Python311\site-packages\urllib3\connection.py", line 704, in connect
    self.sock = sock = self._new_conn()
                       ^^^^^^^^^^^^^^^^
  File "C:\Users\mishr\AppData\Local\Packages\PythonSoftwareFoundation.Python.3.11_qbz5n2kfra8p0\LocalCache\local-packages\Python311\site-packages\urllib3\connection.py", line 205, in _new_conn
    raise NameResolutionError(self.host, self, e) from e
urllib3.exceptions.NameResolutionError: <urllib3.connection.HTTPSConnection object at 0x00000211817E4550>: Failed to resolve 'nonexistent-blog-xyz.com' ([Errno 11001] getaddrinfo failed)

The above exception was the direct cause of the following exception:

Traceback (most recent call last):
  File "C:\Users\mishr\AppData\Local\Packages\PythonSoftwareFoundation.Python.3.11_qbz5n2kfra8p0\LocalCache\local-packages\Python311\site-packages\requests\adapters.py", line 667, in send
    resp = conn.urlopen(
           ^^^^^^^^^^^^^
  File "C:\Users\mishr\AppData\Local\Packages\PythonSoftwareFoundation.Python.3.11_qbz5n2kfra8p0\LocalCache\local-packages\Python311\site-packages\urllib3\connectionpool.py", line 841, in urlopen
    retries = retries.increment(
              ^^^^^^^^^^^^^^^^^^
  File "C:\Users\mishr\AppData\Local\Packages\PythonSoftwareFoundation.Python.3.11_qbz5n2kfra8p0\LocalCache\local-packages\Python311\site-packages\urllib3\util\retry.py", line 519, in increment
    raise MaxRetryError(_pool, url, reason) from reason  # type: ignore[arg-type]
    ^^^^^^^^^^^^^^^^^^^^^^^^^^^^^^^^^^^^^^^^^^^^^^^^^^^
urllib3.exceptions.MaxRetryError: HTTPSConnectionPool(host='nonexistent-blog-xyz.com', port=443): Max retries exceeded with url: / (Caused by NameResolutionError("<urllib3.connection.HTTPSConnection object at 0x00000211817E4550>: Failed to resolve 'nonexistent-blog-xyz.com' ([Errno 11001] getaddrinfo failed)"))

During handling of the above exception, another exception occurred:

Traceback (most recent call last):
  File "C:\Users\mishr\Desktop\OGtool\content_extraction\extractors\blog.py", line 105, in _fetch_url
    response = requests.get(url, headers=self.headers, timeout=30)
               ^^^^^^^^^^^^^^^^^^^^^^^^^^^^^^^^^^^^^^^^^^^^^^^^^^^
  File "C:\Users\mishr\AppData\Local\Packages\PythonSoftwareFoundation.Python.3.11_qbz5n2kfra8p0\LocalCache\local-packages\Python311\site-packages\requests\api.py", line 73, in get
    return request("get", url, params=params, **kwargs)
           ^^^^^^^^^^^^^^^^^^^^^^^^^^^^^^^^^^^^^^^^^^^^
  File "C:\Users\mishr\AppData\Local\Packages\PythonSoftwareFoundation.Python.3.11_qbz5n2kfra8p0\LocalCache\local-packages\Python311\site-packages\requests\api.py", line 59, in request
    return session.request(method=method, url=url, **kwargs)
           ^^^^^^^^^^^^^^^^^^^^^^^^^^^^^^^^^^^^^^^^^^^^^^^^^
  File "C:\Users\mishr\AppData\Local\Packages\PythonSoftwareFoundation.Python.3.11_qbz5n2kfra8p0\LocalCache\local-packages\Python311\site-packages\requests\sessions.py", line 589, in request
    resp = self.send(prep, **send_kwargs)
           ^^^^^^^^^^^^^^^^^^^^^^^^^^^^^^
  File "C:\Users\mishr\AppData\Local\Packages\PythonSoftwareFoundation.Python.3.11_qbz5n2kfra8p0\LocalCache\local-packages\Python311\site-packages\requests\sessions.py", line 703, in send
    r = adapter.send(request, **kwargs)
        ^^^^^^^^^^^^^^^^^^^^^^^^^^^^^^^
  File "C:\Users\mishr\AppData\Local\Packages\PythonSoftwareFoundation.Python.3.11_qbz5n2kfra8p0\LocalCache\local-packages\Python311\site-packages\requests\adapters.py", line 700, in send
    raise ConnectionError(e, request=request)
requests.exceptions.ConnectionError: HTTPSConnectionPool(host='nonexistent-blog-xyz.com', port=443): Max retries exceeded with url: / (Caused by NameResolutionError("<urllib3.connection.HTTPSConnection object at 0x00000211817E4550>: Failed to resolve 'nonexistent-blog-xyz.com' ([Errno 11001] getaddrinfo failed)"))
2025-06-19 00:53:28,022 - GenericBlogExtractor - ERROR - Failed to fetch URL: https://nonexistent-blog-xyz.com/
2025-06-19 00:53:28,024 - ExtractorManager - INFO - Registered extractor: GenericBlogExtractor
2025-06-19 00:53:28,026 - ExtractorManager - INFO - Registered extractor: GitHubExtractor
2025-06-19 00:53:28,027 - ExtractorManager - INFO - Registered extractor: MarkdownExtractor
2025-06-19 00:53:28,028 - ExtractorManager - INFO - Registered extractor: PDFExtractor
2025-06-19 00:53:28,029 - ExtractorManager - INFO - Registered extractor: SubstackExtractor
2025-06-19 00:53:28,030 - root - INFO - Successfully registered 5 extractors
2025-06-19 00:53:28,030 - ExtractorManager - INFO - Using GitHubExtractor for https://github.com/microsoft/vscode
2025-06-19 00:53:28,031 - GitHubExtractor - INFO - Extracting content from GitHub repository: https://github.com/microsoft/vscode
2025-06-19 00:53:47,033 - ExtractorManager - INFO - Registered extractor: GenericBlogExtractor
2025-06-19 00:53:47,065 - ExtractorManager - INFO - Registered extractor: GitHubExtractor
2025-06-19 00:53:47,069 - ExtractorManager - INFO - Registered extractor: MarkdownExtractor
2025-06-19 00:53:47,228 - ExtractorManager - INFO - Registered extractor: PDFExtractor
2025-06-19 00:53:47,231 - ExtractorManager - INFO - Registered extractor: SubstackExtractor
2025-06-19 00:53:47,231 - root - INFO - Successfully registered 5 extractors
2025-06-19 00:53:47,234 - ExtractorManager - INFO - Registered extractor: GenericBlogExtractor
2025-06-19 00:53:47,235 - ExtractorManager - INFO - Registered extractor: GitHubExtractor
2025-06-19 00:53:47,236 - ExtractorManager - INFO - Registered extractor: MarkdownExtractor
2025-06-19 00:53:47,237 - ExtractorManager - INFO - Registered extractor: PDFExtractor
2025-06-19 00:53:47,237 - ExtractorManager - INFO - Registered extractor: SubstackExtractor
2025-06-19 00:53:47,238 - root - INFO - Successfully registered 5 extractors
2025-06-19 00:53:47,241 - ExtractorManager - INFO - Registered extractor: GenericBlogExtractor
2025-06-19 00:53:47,241 - ExtractorManager - INFO - Registered extractor: GitHubExtractor
2025-06-19 00:53:47,243 - ExtractorManager - INFO - Registered extractor: MarkdownExtractor
2025-06-19 00:53:47,243 - ExtractorManager - INFO - Registered extractor: PDFExtractor
2025-06-19 00:53:47,243 - ExtractorManager - INFO - Registered extractor: SubstackExtractor
2025-06-19 00:53:47,244 - root - INFO - Successfully registered 5 extractors
2025-06-19 00:53:47,244 - ExtractorManager - INFO - Using GenericBlogExtractor for https://blog.openai.com/
2025-06-19 00:53:47,244 - GenericBlogExtractor - INFO - Extracting content from generic blog: https://blog.openai.com/
2025-06-19 00:53:47,312 - GenericBlogExtractor - ERROR - Failed to fetch URL https://blog.openai.com/: HTTPSConnectionPool(host='blog.openai.com', port=443): Max retries exceeded with url: / (Caused by NameResolutionError("<urllib3.connection.HTTPSConnection object at 0x00000175E577DE50>: Failed to resolve 'blog.openai.com' ([Errno 11001] getaddrinfo failed)"))
Traceback (most recent call last):
  File "C:\Users\mishr\AppData\Local\Packages\PythonSoftwareFoundation.Python.3.11_qbz5n2kfra8p0\LocalCache\local-packages\Python311\site-packages\urllib3\connection.py", line 198, in _new_conn
    sock = connection.create_connection(
           ^^^^^^^^^^^^^^^^^^^^^^^^^^^^^
  File "C:\Users\mishr\AppData\Local\Packages\PythonSoftwareFoundation.Python.3.11_qbz5n2kfra8p0\LocalCache\local-packages\Python311\site-packages\urllib3\util\connection.py", line 60, in create_connection
    for res in socket.getaddrinfo(host, port, family, socket.SOCK_STREAM):
               ^^^^^^^^^^^^^^^^^^^^^^^^^^^^^^^^^^^^^^^^^^^^^^^^^^^^^^^^^^
  File "C:\Program Files\WindowsApps\PythonSoftwareFoundation.Python.3.11_3.11.2544.0_x64__qbz5n2kfra8p0\Lib\socket.py", line 962, in getaddrinfo
    for res in _socket.getaddrinfo(host, port, family, type, proto, flags):
               ^^^^^^^^^^^^^^^^^^^^^^^^^^^^^^^^^^^^^^^^^^^^^^^^^^^^^^^^^^^
socket.gaierror: [Errno 11001] getaddrinfo failed

The above exception was the direct cause of the following exception:

Traceback (most recent call last):
  File "C:\Users\mishr\AppData\Local\Packages\PythonSoftwareFoundation.Python.3.11_qbz5n2kfra8p0\LocalCache\local-packages\Python311\site-packages\urllib3\connectionpool.py", line 787, in urlopen
    response = self._make_request(
               ^^^^^^^^^^^^^^^^^^^
  File "C:\Users\mishr\AppData\Local\Packages\PythonSoftwareFoundation.Python.3.11_qbz5n2kfra8p0\LocalCache\local-packages\Python311\site-packages\urllib3\connectionpool.py", line 488, in _make_request
    raise new_e
  File "C:\Users\mishr\AppData\Local\Packages\PythonSoftwareFoundation.Python.3.11_qbz5n2kfra8p0\LocalCache\local-packages\Python311\site-packages\urllib3\connectionpool.py", line 464, in _make_request
    self._validate_conn(conn)
  File "C:\Users\mishr\AppData\Local\Packages\PythonSoftwareFoundation.Python.3.11_qbz5n2kfra8p0\LocalCache\local-packages\Python311\site-packages\urllib3\connectionpool.py", line 1093, in _validate_conn
    conn.connect()
  File "C:\Users\mishr\AppData\Local\Packages\PythonSoftwareFoundation.Python.3.11_qbz5n2kfra8p0\LocalCache\local-packages\Python311\site-packages\urllib3\connection.py", line 704, in connect
    self.sock = sock = self._new_conn()
                       ^^^^^^^^^^^^^^^^
  File "C:\Users\mishr\AppData\Local\Packages\PythonSoftwareFoundation.Python.3.11_qbz5n2kfra8p0\LocalCache\local-packages\Python311\site-packages\urllib3\connection.py", line 205, in _new_conn
    raise NameResolutionError(self.host, self, e) from e
urllib3.exceptions.NameResolutionError: <urllib3.connection.HTTPSConnection object at 0x00000175E577DE50>: Failed to resolve 'blog.openai.com' ([Errno 11001] getaddrinfo failed)

The above exception was the direct cause of the following exception:

Traceback (most recent call last):
  File "C:\Users\mishr\AppData\Local\Packages\PythonSoftwareFoundation.Python.3.11_qbz5n2kfra8p0\LocalCache\local-packages\Python311\site-packages\requests\adapters.py", line 667, in send
    resp = conn.urlopen(
           ^^^^^^^^^^^^^
  File "C:\Users\mishr\AppData\Local\Packages\PythonSoftwareFoundation.Python.3.11_qbz5n2kfra8p0\LocalCache\local-packages\Python311\site-packages\urllib3\connectionpool.py", line 841, in urlopen
    retries = retries.increment(
              ^^^^^^^^^^^^^^^^^^
  File "C:\Users\mishr\AppData\Local\Packages\PythonSoftwareFoundation.Python.3.11_qbz5n2kfra8p0\LocalCache\local-packages\Python311\site-packages\urllib3\util\retry.py", line 519, in increment
    raise MaxRetryError(_pool, url, reason) from reason  # type: ignore[arg-type]
    ^^^^^^^^^^^^^^^^^^^^^^^^^^^^^^^^^^^^^^^^^^^^^^^^^^^
urllib3.exceptions.MaxRetryError: HTTPSConnectionPool(host='blog.openai.com', port=443): Max retries exceeded with url: / (Caused by NameResolutionError("<urllib3.connection.HTTPSConnection object at 0x00000175E577DE50>: Failed to resolve 'blog.openai.com' ([Errno 11001] getaddrinfo failed)"))

During handling of the above exception, another exception occurred:

Traceback (most recent call last):
  File "C:\Users\mishr\Desktop\OGtool\content_extraction\extractors\blog.py", line 105, in _fetch_url
    response = requests.get(url, headers=self.headers, timeout=30)
               ^^^^^^^^^^^^^^^^^^^^^^^^^^^^^^^^^^^^^^^^^^^^^^^^^^^
  File "C:\Users\mishr\AppData\Local\Packages\PythonSoftwareFoundation.Python.3.11_qbz5n2kfra8p0\LocalCache\local-packages\Python311\site-packages\requests\api.py", line 73, in get
    return request("get", url, params=params, **kwargs)
           ^^^^^^^^^^^^^^^^^^^^^^^^^^^^^^^^^^^^^^^^^^^^
  File "C:\Users\mishr\AppData\Local\Packages\PythonSoftwareFoundation.Python.3.11_qbz5n2kfra8p0\LocalCache\local-packages\Python311\site-packages\requests\api.py", line 59, in request
    return session.request(method=method, url=url, **kwargs)
           ^^^^^^^^^^^^^^^^^^^^^^^^^^^^^^^^^^^^^^^^^^^^^^^^^
  File "C:\Users\mishr\AppData\Local\Packages\PythonSoftwareFoundation.Python.3.11_qbz5n2kfra8p0\LocalCache\local-packages\Python311\site-packages\requests\sessions.py", line 589, in request
    resp = self.send(prep, **send_kwargs)
           ^^^^^^^^^^^^^^^^^^^^^^^^^^^^^^
  File "C:\Users\mishr\AppData\Local\Packages\PythonSoftwareFoundation.Python.3.11_qbz5n2kfra8p0\LocalCache\local-packages\Python311\site-packages\requests\sessions.py", line 703, in send
    r = adapter.send(request, **kwargs)
        ^^^^^^^^^^^^^^^^^^^^^^^^^^^^^^^
  File "C:\Users\mishr\AppData\Local\Packages\PythonSoftwareFoundation.Python.3.11_qbz5n2kfra8p0\LocalCache\local-packages\Python311\site-packages\requests\adapters.py", line 700, in send
    raise ConnectionError(e, request=request)
requests.exceptions.ConnectionError: HTTPSConnectionPool(host='blog.openai.com', port=443): Max retries exceeded with url: / (Caused by NameResolutionError("<urllib3.connection.HTTPSConnection object at 0x00000175E577DE50>: Failed to resolve 'blog.openai.com' ([Errno 11001] getaddrinfo failed)"))
2025-06-19 00:53:47,321 - GenericBlogExtractor - ERROR - Failed to fetch URL: https://blog.openai.com/
2025-06-19 00:53:47,321 - ExtractorManager - INFO - Using GenericBlogExtractor for https://github.blog/
2025-06-19 00:53:47,322 - GenericBlogExtractor - INFO - Extracting content from generic blog: https://github.blog/
2025-06-19 00:53:47,738 - GenericBlogExtractor - INFO - Extracted 1 item(s) from https://github.blog/
2025-06-19 00:53:47,738 - ExtractorManager - INFO - Using GenericBlogExtractor for https://nonexistent-blog-xyz.com/
2025-06-19 00:53:47,740 - GenericBlogExtractor - INFO - Extracting content from generic blog: https://nonexistent-blog-xyz.com/
2025-06-19 00:53:47,772 - GenericBlogExtractor - ERROR - Failed to fetch URL https://nonexistent-blog-xyz.com/: HTTPSConnectionPool(host='nonexistent-blog-xyz.com', port=443): Max retries exceeded with url: / (Caused by NameResolutionError("<urllib3.connection.HTTPSConnection object at 0x00000175E5A78050>: Failed to resolve 'nonexistent-blog-xyz.com' ([Errno 11001] getaddrinfo failed)"))
Traceback (most recent call last):
  File "C:\Users\mishr\AppData\Local\Packages\PythonSoftwareFoundation.Python.3.11_qbz5n2kfra8p0\LocalCache\local-packages\Python311\site-packages\urllib3\connection.py", line 198, in _new_conn
    sock = connection.create_connection(
           ^^^^^^^^^^^^^^^^^^^^^^^^^^^^^
  File "C:\Users\mishr\AppData\Local\Packages\PythonSoftwareFoundation.Python.3.11_qbz5n2kfra8p0\LocalCache\local-packages\Python311\site-packages\urllib3\util\connection.py", line 60, in create_connection
    for res in socket.getaddrinfo(host, port, family, socket.SOCK_STREAM):
               ^^^^^^^^^^^^^^^^^^^^^^^^^^^^^^^^^^^^^^^^^^^^^^^^^^^^^^^^^^
  File "C:\Program Files\WindowsApps\PythonSoftwareFoundation.Python.3.11_3.11.2544.0_x64__qbz5n2kfra8p0\Lib\socket.py", line 962, in getaddrinfo
    for res in _socket.getaddrinfo(host, port, family, type, proto, flags):
               ^^^^^^^^^^^^^^^^^^^^^^^^^^^^^^^^^^^^^^^^^^^^^^^^^^^^^^^^^^^
socket.gaierror: [Errno 11001] getaddrinfo failed

The above exception was the direct cause of the following exception:

Traceback (most recent call last):
  File "C:\Users\mishr\AppData\Local\Packages\PythonSoftwareFoundation.Python.3.11_qbz5n2kfra8p0\LocalCache\local-packages\Python311\site-packages\urllib3\connectionpool.py", line 787, in urlopen
    response = self._make_request(
               ^^^^^^^^^^^^^^^^^^^
  File "C:\Users\mishr\AppData\Local\Packages\PythonSoftwareFoundation.Python.3.11_qbz5n2kfra8p0\LocalCache\local-packages\Python311\site-packages\urllib3\connectionpool.py", line 488, in _make_request
    raise new_e
  File "C:\Users\mishr\AppData\Local\Packages\PythonSoftwareFoundation.Python.3.11_qbz5n2kfra8p0\LocalCache\local-packages\Python311\site-packages\urllib3\connectionpool.py", line 464, in _make_request
    self._validate_conn(conn)
  File "C:\Users\mishr\AppData\Local\Packages\PythonSoftwareFoundation.Python.3.11_qbz5n2kfra8p0\LocalCache\local-packages\Python311\site-packages\urllib3\connectionpool.py", line 1093, in _validate_conn
    conn.connect()
  File "C:\Users\mishr\AppData\Local\Packages\PythonSoftwareFoundation.Python.3.11_qbz5n2kfra8p0\LocalCache\local-packages\Python311\site-packages\urllib3\connection.py", line 704, in connect
    self.sock = sock = self._new_conn()
                       ^^^^^^^^^^^^^^^^
  File "C:\Users\mishr\AppData\Local\Packages\PythonSoftwareFoundation.Python.3.11_qbz5n2kfra8p0\LocalCache\local-packages\Python311\site-packages\urllib3\connection.py", line 205, in _new_conn
    raise NameResolutionError(self.host, self, e) from e
urllib3.exceptions.NameResolutionError: <urllib3.connection.HTTPSConnection object at 0x00000175E5A78050>: Failed to resolve 'nonexistent-blog-xyz.com' ([Errno 11001] getaddrinfo failed)

The above exception was the direct cause of the following exception:

Traceback (most recent call last):
  File "C:\Users\mishr\AppData\Local\Packages\PythonSoftwareFoundation.Python.3.11_qbz5n2kfra8p0\LocalCache\local-packages\Python311\site-packages\requests\adapters.py", line 667, in send
    resp = conn.urlopen(
           ^^^^^^^^^^^^^
  File "C:\Users\mishr\AppData\Local\Packages\PythonSoftwareFoundation.Python.3.11_qbz5n2kfra8p0\LocalCache\local-packages\Python311\site-packages\urllib3\connectionpool.py", line 841, in urlopen
    retries = retries.increment(
              ^^^^^^^^^^^^^^^^^^
  File "C:\Users\mishr\AppData\Local\Packages\PythonSoftwareFoundation.Python.3.11_qbz5n2kfra8p0\LocalCache\local-packages\Python311\site-packages\urllib3\util\retry.py", line 519, in increment
    raise MaxRetryError(_pool, url, reason) from reason  # type: ignore[arg-type]
    ^^^^^^^^^^^^^^^^^^^^^^^^^^^^^^^^^^^^^^^^^^^^^^^^^^^
urllib3.exceptions.MaxRetryError: HTTPSConnectionPool(host='nonexistent-blog-xyz.com', port=443): Max retries exceeded with url: / (Caused by NameResolutionError("<urllib3.connection.HTTPSConnection object at 0x00000175E5A78050>: Failed to resolve 'nonexistent-blog-xyz.com' ([Errno 11001] getaddrinfo failed)"))

During handling of the above exception, another exception occurred:

Traceback (most recent call last):
  File "C:\Users\mishr\Desktop\OGtool\content_extraction\extractors\blog.py", line 105, in _fetch_url
    response = requests.get(url, headers=self.headers, timeout=30)
               ^^^^^^^^^^^^^^^^^^^^^^^^^^^^^^^^^^^^^^^^^^^^^^^^^^^
  File "C:\Users\mishr\AppData\Local\Packages\PythonSoftwareFoundation.Python.3.11_qbz5n2kfra8p0\LocalCache\local-packages\Python311\site-packages\requests\api.py", line 73, in get
    return request("get", url, params=params, **kwargs)
           ^^^^^^^^^^^^^^^^^^^^^^^^^^^^^^^^^^^^^^^^^^^^
  File "C:\Users\mishr\AppData\Local\Packages\PythonSoftwareFoundation.Python.3.11_qbz5n2kfra8p0\LocalCache\local-packages\Python311\site-packages\requests\api.py", line 59, in request
    return session.request(method=method, url=url, **kwargs)
           ^^^^^^^^^^^^^^^^^^^^^^^^^^^^^^^^^^^^^^^^^^^^^^^^^
  File "C:\Users\mishr\AppData\Local\Packages\PythonSoftwareFoundation.Python.3.11_qbz5n2kfra8p0\LocalCache\local-packages\Python311\site-packages\requests\sessions.py", line 589, in request
    resp = self.send(prep, **send_kwargs)
           ^^^^^^^^^^^^^^^^^^^^^^^^^^^^^^
  File "C:\Users\mishr\AppData\Local\Packages\PythonSoftwareFoundation.Python.3.11_qbz5n2kfra8p0\LocalCache\local-packages\Python311\site-packages\requests\sessions.py", line 703, in send
    r = adapter.send(request, **kwargs)
        ^^^^^^^^^^^^^^^^^^^^^^^^^^^^^^^
  File "C:\Users\mishr\AppData\Local\Packages\PythonSoftwareFoundation.Python.3.11_qbz5n2kfra8p0\LocalCache\local-packages\Python311\site-packages\requests\adapters.py", line 700, in send
    raise ConnectionError(e, request=request)
requests.exceptions.ConnectionError: HTTPSConnectionPool(host='nonexistent-blog-xyz.com', port=443): Max retries exceeded with url: / (Caused by NameResolutionError("<urllib3.connection.HTTPSConnection object at 0x00000175E5A78050>: Failed to resolve 'nonexistent-blog-xyz.com' ([Errno 11001] getaddrinfo failed)"))
2025-06-19 00:53:47,778 - GenericBlogExtractor - ERROR - Failed to fetch URL: https://nonexistent-blog-xyz.com/
2025-06-19 00:53:47,781 - ExtractorManager - INFO - Registered extractor: GenericBlogExtractor
2025-06-19 00:53:47,782 - ExtractorManager - INFO - Registered extractor: GitHubExtractor
2025-06-19 00:53:47,783 - ExtractorManager - INFO - Registered extractor: MarkdownExtractor
2025-06-19 00:53:47,784 - ExtractorManager - INFO - Registered extractor: PDFExtractor
2025-06-19 00:53:47,785 - ExtractorManager - INFO - Registered extractor: SubstackExtractor
2025-06-19 00:53:47,786 - root - INFO - Successfully registered 5 extractors
2025-06-19 00:53:47,786 - ExtractorManager - INFO - Using GitHubExtractor for https://github.com/microsoft/vscode
2025-06-19 00:53:47,787 - GitHubExtractor - INFO - Extracting content from GitHub repository: https://github.com/microsoft/vscode
2025-06-19 00:53:48,717 - ExtractorManager - INFO - Using GitHubExtractor for https://github.com/nonexistent/repo
2025-06-19 00:53:48,719 - GitHubExtractor - INFO - Extracting content from GitHub repository: https://github.com/nonexistent/repo
2025-06-19 00:53:48,903 - GitHubExtractor - WARNING - No README found for nonexistent/repo
2025-06-19 00:53:49,619 - ExtractorManager - INFO - Registered extractor: GenericBlogExtractor
2025-06-19 00:53:49,621 - ExtractorManager - INFO - Registered extractor: GitHubExtractor
2025-06-19 00:53:49,622 - ExtractorManager - INFO - Registered extractor: MarkdownExtractor
2025-06-19 00:53:49,623 - ExtractorManager - INFO - Registered extractor: PDFExtractor
2025-06-19 00:53:49,624 - ExtractorManager - INFO - Registered extractor: SubstackExtractor
2025-06-19 00:53:49,625 - root - INFO - Successfully registered 5 extractors
2025-06-19 00:53:49,626 - ExtractorManager - INFO - Using MarkdownExtractor for test_document.md
2025-06-19 00:53:49,627 - MarkdownExtractor - INFO - Extracting content from markdown file: test_document.md
2025-06-19 00:53:49,657 - ExtractorManager - INFO - Registered extractor: GenericBlogExtractor
2025-06-19 00:53:49,659 - ExtractorManager - INFO - Registered extractor: GitHubExtractor
2025-06-19 00:53:49,660 - ExtractorManager - INFO - Registered extractor: MarkdownExtractor
2025-06-19 00:53:49,661 - ExtractorManager - INFO - Registered extractor: PDFExtractor
2025-06-19 00:53:49,662 - ExtractorManager - INFO - Registered extractor: SubstackExtractor
2025-06-19 00:53:49,664 - root - INFO - Successfully registered 5 extractors
2025-06-19 00:53:49,664 - ExtractorManager - INFO - Using GenericBlogExtractor for https://stratechery.com/
2025-06-19 00:53:49,666 - GenericBlogExtractor - INFO - Extracting content from generic blog: https://stratechery.com/
2025-06-19 00:53:51,602 - GenericBlogExtractor - INFO - Extracted 1 item(s) from https://stratechery.com/
2025-06-19 00:53:51,606 - ExtractorManager - INFO - Registered extractor: GenericBlogExtractor
2025-06-19 00:53:51,608 - ExtractorManager - INFO - Registered extractor: GitHubExtractor
2025-06-19 00:53:51,610 - ExtractorManager - INFO - Registered extractor: MarkdownExtractor
2025-06-19 00:53:51,611 - ExtractorManager - INFO - Registered extractor: PDFExtractor
2025-06-19 00:53:51,612 - ExtractorManager - INFO - Registered extractor: SubstackExtractor
2025-06-19 00:53:51,614 - root - INFO - Successfully registered 5 extractors
2025-06-19 00:53:51,614 - ExtractorManager - INFO - Using MarkdownExtractor for test_document.md
2025-06-19 00:53:51,615 - MarkdownExtractor - INFO - Extracting content from markdown file: test_document.md
2025-06-19 00:53:51,618 - ExtractorManager - INFO - Saved 1 items to test_output.json
2025-06-19 00:54:44,542 - ExtractorManager - INFO - Registered extractor: GenericBlogExtractor
2025-06-19 00:54:44,574 - ExtractorManager - INFO - Registered extractor: GitHubExtractor
2025-06-19 00:54:44,578 - ExtractorManager - INFO - Registered extractor: MarkdownExtractor
2025-06-19 00:54:44,727 - ExtractorManager - INFO - Registered extractor: PDFExtractor
2025-06-19 00:54:44,729 - ExtractorManager - INFO - Registered extractor: SubstackExtractor
2025-06-19 00:54:44,729 - root - INFO - Successfully registered 5 extractors
2025-06-19 00:54:44,731 - ExtractorManager - INFO - Registered extractor: GenericBlogExtractor
2025-06-19 00:54:44,732 - ExtractorManager - INFO - Registered extractor: GitHubExtractor
2025-06-19 00:54:44,733 - ExtractorManager - INFO - Registered extractor: MarkdownExtractor
2025-06-19 00:54:44,734 - ExtractorManager - INFO - Registered extractor: PDFExtractor
2025-06-19 00:54:44,734 - ExtractorManager - INFO - Registered extractor: SubstackExtractor
2025-06-19 00:54:44,735 - root - INFO - Successfully registered 5 extractors
2025-06-19 00:54:44,738 - ExtractorManager - INFO - Registered extractor: GenericBlogExtractor
2025-06-19 00:54:44,739 - ExtractorManager - INFO - Registered extractor: GitHubExtractor
2025-06-19 00:54:44,740 - ExtractorManager - INFO - Registered extractor: MarkdownExtractor
2025-06-19 00:54:44,741 - ExtractorManager - INFO - Registered extractor: PDFExtractor
2025-06-19 00:54:44,742 - ExtractorManager - INFO - Registered extractor: SubstackExtractor
2025-06-19 00:54:44,743 - root - INFO - Successfully registered 5 extractors
2025-06-19 00:54:44,743 - ExtractorManager - INFO - Using GenericBlogExtractor for https://blog.openai.com/
2025-06-19 00:54:44,744 - GenericBlogExtractor - INFO - Extracting content from generic blog: https://blog.openai.com/
2025-06-19 00:54:44,846 - GenericBlogExtractor - ERROR - Failed to fetch URL https://blog.openai.com/: HTTPSConnectionPool(host='blog.openai.com', port=443): Max retries exceeded with url: / (Caused by NameResolutionError("<urllib3.connection.HTTPSConnection object at 0x0000029FF527DDD0>: Failed to resolve 'blog.openai.com' ([Errno 11001] getaddrinfo failed)"))
Traceback (most recent call last):
  File "C:\Users\mishr\AppData\Local\Packages\PythonSoftwareFoundation.Python.3.11_qbz5n2kfra8p0\LocalCache\local-packages\Python311\site-packages\urllib3\connection.py", line 198, in _new_conn
    sock = connection.create_connection(
           ^^^^^^^^^^^^^^^^^^^^^^^^^^^^^
  File "C:\Users\mishr\AppData\Local\Packages\PythonSoftwareFoundation.Python.3.11_qbz5n2kfra8p0\LocalCache\local-packages\Python311\site-packages\urllib3\util\connection.py", line 60, in create_connection
    for res in socket.getaddrinfo(host, port, family, socket.SOCK_STREAM):
               ^^^^^^^^^^^^^^^^^^^^^^^^^^^^^^^^^^^^^^^^^^^^^^^^^^^^^^^^^^
  File "C:\Program Files\WindowsApps\PythonSoftwareFoundation.Python.3.11_3.11.2544.0_x64__qbz5n2kfra8p0\Lib\socket.py", line 962, in getaddrinfo
    for res in _socket.getaddrinfo(host, port, family, type, proto, flags):
               ^^^^^^^^^^^^^^^^^^^^^^^^^^^^^^^^^^^^^^^^^^^^^^^^^^^^^^^^^^^
socket.gaierror: [Errno 11001] getaddrinfo failed

The above exception was the direct cause of the following exception:

Traceback (most recent call last):
  File "C:\Users\mishr\AppData\Local\Packages\PythonSoftwareFoundation.Python.3.11_qbz5n2kfra8p0\LocalCache\local-packages\Python311\site-packages\urllib3\connectionpool.py", line 787, in urlopen
    response = self._make_request(
               ^^^^^^^^^^^^^^^^^^^
  File "C:\Users\mishr\AppData\Local\Packages\PythonSoftwareFoundation.Python.3.11_qbz5n2kfra8p0\LocalCache\local-packages\Python311\site-packages\urllib3\connectionpool.py", line 488, in _make_request
    raise new_e
  File "C:\Users\mishr\AppData\Local\Packages\PythonSoftwareFoundation.Python.3.11_qbz5n2kfra8p0\LocalCache\local-packages\Python311\site-packages\urllib3\connectionpool.py", line 464, in _make_request
    self._validate_conn(conn)
  File "C:\Users\mishr\AppData\Local\Packages\PythonSoftwareFoundation.Python.3.11_qbz5n2kfra8p0\LocalCache\local-packages\Python311\site-packages\urllib3\connectionpool.py", line 1093, in _validate_conn
    conn.connect()
  File "C:\Users\mishr\AppData\Local\Packages\PythonSoftwareFoundation.Python.3.11_qbz5n2kfra8p0\LocalCache\local-packages\Python311\site-packages\urllib3\connection.py", line 704, in connect
    self.sock = sock = self._new_conn()
                       ^^^^^^^^^^^^^^^^
  File "C:\Users\mishr\AppData\Local\Packages\PythonSoftwareFoundation.Python.3.11_qbz5n2kfra8p0\LocalCache\local-packages\Python311\site-packages\urllib3\connection.py", line 205, in _new_conn
    raise NameResolutionError(self.host, self, e) from e
urllib3.exceptions.NameResolutionError: <urllib3.connection.HTTPSConnection object at 0x0000029FF527DDD0>: Failed to resolve 'blog.openai.com' ([Errno 11001] getaddrinfo failed)

The above exception was the direct cause of the following exception:

Traceback (most recent call last):
  File "C:\Users\mishr\AppData\Local\Packages\PythonSoftwareFoundation.Python.3.11_qbz5n2kfra8p0\LocalCache\local-packages\Python311\site-packages\requests\adapters.py", line 667, in send
    resp = conn.urlopen(
           ^^^^^^^^^^^^^
  File "C:\Users\mishr\AppData\Local\Packages\PythonSoftwareFoundation.Python.3.11_qbz5n2kfra8p0\LocalCache\local-packages\Python311\site-packages\urllib3\connectionpool.py", line 841, in urlopen
    retries = retries.increment(
              ^^^^^^^^^^^^^^^^^^
  File "C:\Users\mishr\AppData\Local\Packages\PythonSoftwareFoundation.Python.3.11_qbz5n2kfra8p0\LocalCache\local-packages\Python311\site-packages\urllib3\util\retry.py", line 519, in increment
    raise MaxRetryError(_pool, url, reason) from reason  # type: ignore[arg-type]
    ^^^^^^^^^^^^^^^^^^^^^^^^^^^^^^^^^^^^^^^^^^^^^^^^^^^
urllib3.exceptions.MaxRetryError: HTTPSConnectionPool(host='blog.openai.com', port=443): Max retries exceeded with url: / (Caused by NameResolutionError("<urllib3.connection.HTTPSConnection object at 0x0000029FF527DDD0>: Failed to resolve 'blog.openai.com' ([Errno 11001] getaddrinfo failed)"))

During handling of the above exception, another exception occurred:

Traceback (most recent call last):
  File "C:\Users\mishr\Desktop\OGtool\content_extraction\extractors\blog.py", line 105, in _fetch_url
    response = requests.get(url, headers=self.headers, timeout=30)
               ^^^^^^^^^^^^^^^^^^^^^^^^^^^^^^^^^^^^^^^^^^^^^^^^^^^
  File "C:\Users\mishr\AppData\Local\Packages\PythonSoftwareFoundation.Python.3.11_qbz5n2kfra8p0\LocalCache\local-packages\Python311\site-packages\requests\api.py", line 73, in get
    return request("get", url, params=params, **kwargs)
           ^^^^^^^^^^^^^^^^^^^^^^^^^^^^^^^^^^^^^^^^^^^^
  File "C:\Users\mishr\AppData\Local\Packages\PythonSoftwareFoundation.Python.3.11_qbz5n2kfra8p0\LocalCache\local-packages\Python311\site-packages\requests\api.py", line 59, in request
    return session.request(method=method, url=url, **kwargs)
           ^^^^^^^^^^^^^^^^^^^^^^^^^^^^^^^^^^^^^^^^^^^^^^^^^
  File "C:\Users\mishr\AppData\Local\Packages\PythonSoftwareFoundation.Python.3.11_qbz5n2kfra8p0\LocalCache\local-packages\Python311\site-packages\requests\sessions.py", line 589, in request
    resp = self.send(prep, **send_kwargs)
           ^^^^^^^^^^^^^^^^^^^^^^^^^^^^^^
  File "C:\Users\mishr\AppData\Local\Packages\PythonSoftwareFoundation.Python.3.11_qbz5n2kfra8p0\LocalCache\local-packages\Python311\site-packages\requests\sessions.py", line 703, in send
    r = adapter.send(request, **kwargs)
        ^^^^^^^^^^^^^^^^^^^^^^^^^^^^^^^
  File "C:\Users\mishr\AppData\Local\Packages\PythonSoftwareFoundation.Python.3.11_qbz5n2kfra8p0\LocalCache\local-packages\Python311\site-packages\requests\adapters.py", line 700, in send
    raise ConnectionError(e, request=request)
requests.exceptions.ConnectionError: HTTPSConnectionPool(host='blog.openai.com', port=443): Max retries exceeded with url: / (Caused by NameResolutionError("<urllib3.connection.HTTPSConnection object at 0x0000029FF527DDD0>: Failed to resolve 'blog.openai.com' ([Errno 11001] getaddrinfo failed)"))
2025-06-19 00:54:44,855 - GenericBlogExtractor - ERROR - Failed to fetch URL: https://blog.openai.com/
2025-06-19 00:54:44,856 - ExtractorManager - INFO - Using GenericBlogExtractor for https://github.blog/
2025-06-19 00:54:44,856 - GenericBlogExtractor - INFO - Extracting content from generic blog: https://github.blog/
2025-06-19 00:54:45,227 - GenericBlogExtractor - INFO - Extracted 1 item(s) from https://github.blog/
2025-06-19 00:54:45,228 - ExtractorManager - INFO - Using GenericBlogExtractor for https://nonexistent-blog-xyz.com/
2025-06-19 00:54:45,229 - GenericBlogExtractor - INFO - Extracting content from generic blog: https://nonexistent-blog-xyz.com/
2025-06-19 00:54:45,261 - GenericBlogExtractor - ERROR - Failed to fetch URL https://nonexistent-blog-xyz.com/: HTTPSConnectionPool(host='nonexistent-blog-xyz.com', port=443): Max retries exceeded with url: / (Caused by NameResolutionError("<urllib3.connection.HTTPSConnection object at 0x0000029FF55A5110>: Failed to resolve 'nonexistent-blog-xyz.com' ([Errno 11001] getaddrinfo failed)"))
Traceback (most recent call last):
  File "C:\Users\mishr\AppData\Local\Packages\PythonSoftwareFoundation.Python.3.11_qbz5n2kfra8p0\LocalCache\local-packages\Python311\site-packages\urllib3\connection.py", line 198, in _new_conn
    sock = connection.create_connection(
           ^^^^^^^^^^^^^^^^^^^^^^^^^^^^^
  File "C:\Users\mishr\AppData\Local\Packages\PythonSoftwareFoundation.Python.3.11_qbz5n2kfra8p0\LocalCache\local-packages\Python311\site-packages\urllib3\util\connection.py", line 60, in create_connection
    for res in socket.getaddrinfo(host, port, family, socket.SOCK_STREAM):
               ^^^^^^^^^^^^^^^^^^^^^^^^^^^^^^^^^^^^^^^^^^^^^^^^^^^^^^^^^^
  File "C:\Program Files\WindowsApps\PythonSoftwareFoundation.Python.3.11_3.11.2544.0_x64__qbz5n2kfra8p0\Lib\socket.py", line 962, in getaddrinfo
    for res in _socket.getaddrinfo(host, port, family, type, proto, flags):
               ^^^^^^^^^^^^^^^^^^^^^^^^^^^^^^^^^^^^^^^^^^^^^^^^^^^^^^^^^^^
socket.gaierror: [Errno 11001] getaddrinfo failed

The above exception was the direct cause of the following exception:

Traceback (most recent call last):
  File "C:\Users\mishr\AppData\Local\Packages\PythonSoftwareFoundation.Python.3.11_qbz5n2kfra8p0\LocalCache\local-packages\Python311\site-packages\urllib3\connectionpool.py", line 787, in urlopen
    response = self._make_request(
               ^^^^^^^^^^^^^^^^^^^
  File "C:\Users\mishr\AppData\Local\Packages\PythonSoftwareFoundation.Python.3.11_qbz5n2kfra8p0\LocalCache\local-packages\Python311\site-packages\urllib3\connectionpool.py", line 488, in _make_request
    raise new_e
  File "C:\Users\mishr\AppData\Local\Packages\PythonSoftwareFoundation.Python.3.11_qbz5n2kfra8p0\LocalCache\local-packages\Python311\site-packages\urllib3\connectionpool.py", line 464, in _make_request
    self._validate_conn(conn)
  File "C:\Users\mishr\AppData\Local\Packages\PythonSoftwareFoundation.Python.3.11_qbz5n2kfra8p0\LocalCache\local-packages\Python311\site-packages\urllib3\connectionpool.py", line 1093, in _validate_conn
    conn.connect()
  File "C:\Users\mishr\AppData\Local\Packages\PythonSoftwareFoundation.Python.3.11_qbz5n2kfra8p0\LocalCache\local-packages\Python311\site-packages\urllib3\connection.py", line 704, in connect
    self.sock = sock = self._new_conn()
                       ^^^^^^^^^^^^^^^^
  File "C:\Users\mishr\AppData\Local\Packages\PythonSoftwareFoundation.Python.3.11_qbz5n2kfra8p0\LocalCache\local-packages\Python311\site-packages\urllib3\connection.py", line 205, in _new_conn
    raise NameResolutionError(self.host, self, e) from e
urllib3.exceptions.NameResolutionError: <urllib3.connection.HTTPSConnection object at 0x0000029FF55A5110>: Failed to resolve 'nonexistent-blog-xyz.com' ([Errno 11001] getaddrinfo failed)

The above exception was the direct cause of the following exception:

Traceback (most recent call last):
  File "C:\Users\mishr\AppData\Local\Packages\PythonSoftwareFoundation.Python.3.11_qbz5n2kfra8p0\LocalCache\local-packages\Python311\site-packages\requests\adapters.py", line 667, in send
    resp = conn.urlopen(
           ^^^^^^^^^^^^^
  File "C:\Users\mishr\AppData\Local\Packages\PythonSoftwareFoundation.Python.3.11_qbz5n2kfra8p0\LocalCache\local-packages\Python311\site-packages\urllib3\connectionpool.py", line 841, in urlopen
    retries = retries.increment(
              ^^^^^^^^^^^^^^^^^^
  File "C:\Users\mishr\AppData\Local\Packages\PythonSoftwareFoundation.Python.3.11_qbz5n2kfra8p0\LocalCache\local-packages\Python311\site-packages\urllib3\util\retry.py", line 519, in increment
    raise MaxRetryError(_pool, url, reason) from reason  # type: ignore[arg-type]
    ^^^^^^^^^^^^^^^^^^^^^^^^^^^^^^^^^^^^^^^^^^^^^^^^^^^
urllib3.exceptions.MaxRetryError: HTTPSConnectionPool(host='nonexistent-blog-xyz.com', port=443): Max retries exceeded with url: / (Caused by NameResolutionError("<urllib3.connection.HTTPSConnection object at 0x0000029FF55A5110>: Failed to resolve 'nonexistent-blog-xyz.com' ([Errno 11001] getaddrinfo failed)"))

During handling of the above exception, another exception occurred:

Traceback (most recent call last):
  File "C:\Users\mishr\Desktop\OGtool\content_extraction\extractors\blog.py", line 105, in _fetch_url
    response = requests.get(url, headers=self.headers, timeout=30)
               ^^^^^^^^^^^^^^^^^^^^^^^^^^^^^^^^^^^^^^^^^^^^^^^^^^^
  File "C:\Users\mishr\AppData\Local\Packages\PythonSoftwareFoundation.Python.3.11_qbz5n2kfra8p0\LocalCache\local-packages\Python311\site-packages\requests\api.py", line 73, in get
    return request("get", url, params=params, **kwargs)
           ^^^^^^^^^^^^^^^^^^^^^^^^^^^^^^^^^^^^^^^^^^^^
  File "C:\Users\mishr\AppData\Local\Packages\PythonSoftwareFoundation.Python.3.11_qbz5n2kfra8p0\LocalCache\local-packages\Python311\site-packages\requests\api.py", line 59, in request
    return session.request(method=method, url=url, **kwargs)
           ^^^^^^^^^^^^^^^^^^^^^^^^^^^^^^^^^^^^^^^^^^^^^^^^^
  File "C:\Users\mishr\AppData\Local\Packages\PythonSoftwareFoundation.Python.3.11_qbz5n2kfra8p0\LocalCache\local-packages\Python311\site-packages\requests\sessions.py", line 589, in request
    resp = self.send(prep, **send_kwargs)
           ^^^^^^^^^^^^^^^^^^^^^^^^^^^^^^
  File "C:\Users\mishr\AppData\Local\Packages\PythonSoftwareFoundation.Python.3.11_qbz5n2kfra8p0\LocalCache\local-packages\Python311\site-packages\requests\sessions.py", line 703, in send
    r = adapter.send(request, **kwargs)
        ^^^^^^^^^^^^^^^^^^^^^^^^^^^^^^^
  File "C:\Users\mishr\AppData\Local\Packages\PythonSoftwareFoundation.Python.3.11_qbz5n2kfra8p0\LocalCache\local-packages\Python311\site-packages\requests\adapters.py", line 700, in send
    raise ConnectionError(e, request=request)
requests.exceptions.ConnectionError: HTTPSConnectionPool(host='nonexistent-blog-xyz.com', port=443): Max retries exceeded with url: / (Caused by NameResolutionError("<urllib3.connection.HTTPSConnection object at 0x0000029FF55A5110>: Failed to resolve 'nonexistent-blog-xyz.com' ([Errno 11001] getaddrinfo failed)"))
2025-06-19 00:54:45,266 - GenericBlogExtractor - ERROR - Failed to fetch URL: https://nonexistent-blog-xyz.com/
2025-06-19 00:54:45,268 - ExtractorManager - INFO - Registered extractor: GenericBlogExtractor
2025-06-19 00:54:45,270 - ExtractorManager - INFO - Registered extractor: GitHubExtractor
2025-06-19 00:54:45,271 - ExtractorManager - INFO - Registered extractor: MarkdownExtractor
2025-06-19 00:54:45,271 - ExtractorManager - INFO - Registered extractor: PDFExtractor
2025-06-19 00:54:45,273 - ExtractorManager - INFO - Registered extractor: SubstackExtractor
2025-06-19 00:54:45,274 - root - INFO - Successfully registered 5 extractors
2025-06-19 00:54:45,275 - ExtractorManager - INFO - Using GitHubExtractor for https://github.com/microsoft/vscode
2025-06-19 00:54:45,276 - GitHubExtractor - INFO - Extracting content from GitHub repository: https://github.com/microsoft/vscode
2025-06-19 00:54:46,295 - ExtractorManager - INFO - Using GitHubExtractor for https://github.com/nonexistent/repo
2025-06-19 00:54:46,296 - GitHubExtractor - INFO - Extracting content from GitHub repository: https://github.com/nonexistent/repo
2025-06-19 00:54:46,565 - GitHubExtractor - WARNING - No README found for nonexistent/repo
2025-06-19 00:54:47,293 - ExtractorManager - INFO - Registered extractor: GenericBlogExtractor
2025-06-19 00:54:47,294 - ExtractorManager - INFO - Registered extractor: GitHubExtractor
2025-06-19 00:54:47,297 - ExtractorManager - INFO - Registered extractor: MarkdownExtractor
2025-06-19 00:54:47,298 - ExtractorManager - INFO - Registered extractor: PDFExtractor
2025-06-19 00:54:47,300 - ExtractorManager - INFO - Registered extractor: SubstackExtractor
2025-06-19 00:54:47,301 - root - INFO - Successfully registered 5 extractors
2025-06-19 00:54:47,302 - ExtractorManager - INFO - Using MarkdownExtractor for test_document.md
2025-06-19 00:54:47,304 - MarkdownExtractor - INFO - Extracting content from markdown file: test_document.md
2025-06-19 00:54:47,311 - ExtractorManager - INFO - Registered extractor: GenericBlogExtractor
2025-06-19 00:54:47,313 - ExtractorManager - INFO - Registered extractor: GitHubExtractor
2025-06-19 00:54:47,314 - ExtractorManager - INFO - Registered extractor: MarkdownExtractor
2025-06-19 00:54:47,316 - ExtractorManager - INFO - Registered extractor: PDFExtractor
2025-06-19 00:54:47,317 - ExtractorManager - INFO - Registered extractor: SubstackExtractor
2025-06-19 00:54:47,319 - root - INFO - Successfully registered 5 extractors
2025-06-19 00:54:47,319 - ExtractorManager - INFO - Using GenericBlogExtractor for https://stratechery.com/
2025-06-19 00:54:47,321 - GenericBlogExtractor - INFO - Extracting content from generic blog: https://stratechery.com/
2025-06-19 00:54:48,999 - GenericBlogExtractor - INFO - Extracted 1 item(s) from https://stratechery.com/
2025-06-19 00:54:49,004 - ExtractorManager - INFO - Registered extractor: GenericBlogExtractor
2025-06-19 00:54:49,006 - ExtractorManager - INFO - Registered extractor: GitHubExtractor
2025-06-19 00:54:49,008 - ExtractorManager - INFO - Registered extractor: MarkdownExtractor
2025-06-19 00:54:49,009 - ExtractorManager - INFO - Registered extractor: PDFExtractor
2025-06-19 00:54:49,011 - ExtractorManager - INFO - Registered extractor: SubstackExtractor
2025-06-19 00:54:49,012 - root - INFO - Successfully registered 5 extractors
2025-06-19 00:54:49,013 - ExtractorManager - INFO - Using MarkdownExtractor for test_document.md
2025-06-19 00:54:49,014 - MarkdownExtractor - INFO - Extracting content from markdown file: test_document.md
2025-06-19 00:54:49,016 - ExtractorManager - INFO - Saved 1 items to test_output.json
